<!--
  Inspire Hand Left — MuJoCo MJCF
  All body/joint/actuator names prefixed with "l_" to avoid conflicts with right hand.
  Root body "inspire_palm_l" with freejoint "palm_free_l" for weld-based mocap control.
  Actuator order (indices 12..23 when included after right hand):
    [0]  l_th_yaw_act    thumb_proximal_yaw_joint
    [1]  l_th_pitch_act  thumb_proximal_pitch_joint
    [2]  l_th_int_act    thumb_intermediate_joint
    [3]  l_th_dis_act    thumb_distal_joint
    [4]  l_if_prx_act    index_proximal_joint
    [5]  l_if_int_act    index_intermediate_joint
    [6]  l_mf_prx_act    middle_proximal_joint
    [7]  l_mf_int_act    middle_intermediate_joint
    [8]  l_rf_prx_act    ring_proximal_joint
    [9]  l_rf_int_act    ring_intermediate_joint
    [10] l_pk_prx_act    pinky_proximal_joint
    [11] l_pk_int_act    pinky_intermediate_joint
-->
<mujoco model="inspire_hand_left_body">
  <compiler angle="radian"/>

  <default>
    <joint damping="0.05" frictionloss="0.001" armature="0.001"/>
    <geom contype="1" conaffinity="1" condim="3" friction="1 0.01 0.001"/>
  </default>

  <asset>
    <mesh name="left_base_link"           file="left_base_link.obj"/>
    <mesh name="left_thumb_proximal_base" file="left_thumb_proximal_base.obj"/>
    <mesh name="left_thumb_proximal"      file="left_thumb_proximal.obj"/>
    <mesh name="left_thumb_intermediate"  file="left_thumb_intermediate.obj"/>
    <mesh name="left_thumb_distal"        file="left_thumb_distal.obj"/>
    <mesh name="left_index_proximal"      file="left_index_proximal.obj"/>
    <mesh name="left_index_intermediate"  file="left_index_intermediate.obj"/>
    <mesh name="left_middle_intermediate" file="left_middle_intermediate.obj"/>
    <mesh name="left_pinky_intermediate"  file="left_pinky_intermediate.obj"/>
  </asset>

  <worldbody>
    <body name="inspire_palm_l" pos="0 0.3 0.3">
      <freejoint name="palm_free_l"/>

      <geom type="mesh" contype="0" conaffinity="0" group="1" density="0" mesh="left_base_link"/>
      <geom size="0.028 0.0139"            pos="0 -0.0136 0"         quat="0.707109 0.707105 0 0" type="cylinder"/>
      <geom size="0.01955 0.0101 0.0287"   pos="-0.0032 -0.038 0"    type="box"/>
      <geom size="0.01955 0.02 0.0407"     pos="-0.0032 -0.0682 0"   type="box"/>
      <geom size="0.0161 0.02 0.0407"      pos="0 -0.1081 0"         type="box"/>
      <geom size="0.00625 0.00555 0.00445" pos="-0.0016 -0.134 -0.0309" type="box"/>
      <geom size="0.00625 0.00555 0.00445" pos="-0.0016 -0.134 -0.0118" type="box"/>
      <geom size="0.00625 0.00555 0.00445" pos="-0.0016 -0.134 0.007"   type="box"/>
      <geom size="0.00625 0.00555 0.00445" pos="-0.0016 -0.134 0.0262"  type="box"/>

      <!-- Thumb -->
      <body name="l_thumb_proximal_base" pos="-0.01696 -0.0691 0.02045" quat="0.499998 0.5 -0.5 0.500002">
        <inertial pos="0.0048817 0.0009382 -0.00722" quat="0.408023 0.323596 0.515015 0.680854"
                  mass="0.0018869" diaginertia="8.66026e-08 6.8732e-08 4.94194e-08"/>
        <joint name="l_thumb_proximal_yaw_joint"   pos="0 0 0" axis="0 0 1" range="0 1.308" actuatorfrcrange="-1 1"/>
        <geom type="mesh" contype="0" conaffinity="0" group="1" density="0" mesh="left_thumb_proximal_base"/>
        <geom type="mesh" mesh="left_thumb_proximal_base"/>

        <body name="l_thumb_proximal" pos="0.0099867 0.0098242 -0.0089" quat="0.704571 -0.704573 -0.0598169 0.0598167">
          <inertial pos="0.021932 -0.012785 -0.0080386" quat="0.254474 0.660716 -0.251893 0.659733"
                    mass="0.0066075" diaginertia="2.78601e-06 2.43933e-06 8.64566e-07"/>
          <joint name="l_thumb_proximal_pitch_joint" pos="0 0 0" axis="0 0 -1" range="0 0.6" actuatorfrcrange="-1 1"/>
          <geom type="mesh" contype="0" conaffinity="0" group="1" density="0" mesh="left_thumb_proximal"/>
          <geom type="mesh" mesh="left_thumb_proximal"/>

          <body name="l_thumb_intermediate" pos="0.04407 -0.034553 -0.0008">
            <inertial pos="0.0095544 0.0016282 -0.0071997" quat="0.307389 0.636718 -0.307548 0.636802"
                      mass="0.0037847" diaginertia="4.6531e-07 4.48089e-07 2.45661e-07"/>
            <joint name="l_thumb_intermediate_joint" pos="0 0 0" axis="0 0 -1" range="0 0.8" actuatorfrcrange="-1 1"/>
            <geom type="mesh" contype="0" conaffinity="0" group="1" density="0" mesh="left_thumb_intermediate"/>
            <geom type="mesh" mesh="left_thumb_intermediate"/>

            <body name="l_thumb_distal" pos="0.020248 -0.010156 -0.0012">
              <inertial pos="0.0092888 -0.0049529 -0.0060033" quat="0.266294 0.655967 -0.262806 0.655537"
                        mass="0.0033441" diaginertia="2.0026e-07 1.95247e-07 8.1593e-08"/>
              <joint name="l_thumb_distal_joint" pos="0 0 0" axis="0 0 -1" range="0 0.4" actuatorfrcrange="-1 1"/>
              <geom type="mesh" contype="0" conaffinity="0" group="1" density="0" mesh="left_thumb_distal"/>
              <geom type="mesh" mesh="left_thumb_distal"/>
            </body>
          </body>
        </body>
      </body>

      <!-- Index finger -->
      <body name="l_index_proximal" pos="0.00028533 -0.13653 0.032268" quat="0.999848 -0.0174526 0 0">
        <inertial pos="0.0012259 -0.011942 -0.0060001" quat="0.49121 0.50867 -0.491172 0.508643"
                  mass="0.0042403" diaginertia="6.9398e-07 6.62871e-07 2.10909e-07"/>
        <joint name="l_index_proximal_joint" pos="0 0 0" axis="0 0 -1" range="0 1.47" actuatorfrcrange="-1 1"/>
        <geom type="mesh" contype="0" conaffinity="0" group="1" density="0" mesh="left_index_proximal"/>
        <geom type="mesh" mesh="left_index_proximal"/>

        <body name="l_index_intermediate" pos="-0.0026138 -0.032026 -0.001">
          <inertial pos="0.0019697 -0.019589 -0.005" quat="0.531152 0.466773 -0.531153 0.466773"
                    mass="0.0045683" diaginertia="7.8179e-07 7.72465e-07 8.47212e-08"/>
          <joint name="l_index_intermediate_joint" pos="0 0 0" axis="0 0 -1" range="-0.04545 1.56" actuatorfrcrange="-1 1"/>
          <geom type="mesh" contype="0" conaffinity="0" group="1" density="0" mesh="left_index_intermediate"/>
          <geom type="mesh" mesh="left_index_intermediate"/>
        </body>
      </body>

      <!-- Middle finger -->
      <body name="l_middle_proximal" pos="0.00028533 -0.1371 0.01295">
        <inertial pos="0.001297 -0.011934 -0.0060001" quat="0.489693 0.510131 -0.489653 0.510105"
                  mass="0.0042403" diaginertia="6.9397e-07 6.62865e-07 2.10915e-07"/>
        <joint name="l_middle_proximal_joint" pos="0 0 0" axis="0 0 -1" range="0 1.47" actuatorfrcrange="-1 1"/>
        <geom type="mesh" contype="0" conaffinity="0" group="1" density="0" mesh="left_index_proximal"/>
        <geom type="mesh" mesh="left_index_proximal"/>

        <body name="l_middle_intermediate" pos="-0.0024229 -0.032041 -0.001">
          <inertial pos="0.001921 -0.020796 -0.005" quat="0.531627 0.466148 -0.531705 0.466229"
                    mass="0.0050396" diaginertia="9.8384e-07 9.73279e-07 9.14014e-08"/>
          <joint name="l_middle_intermediate_joint" pos="0 0 0" axis="0 0 -1" range="-0.04545 1.56" actuatorfrcrange="-1 1"/>
          <geom type="mesh" contype="0" conaffinity="0" group="1" density="0" mesh="left_middle_intermediate"/>
          <geom type="mesh" mesh="left_middle_intermediate"/>
        </body>
      </body>

      <!-- Ring finger -->
      <body name="l_ring_proximal" pos="0.00028533 -0.13691 -0.0062872" quat="0.999657 0.026177 0 0">
        <inertial pos="0.001297 -0.011934 -0.0060002" quat="0.489691 0.510129 -0.489654 0.510107"
                  mass="0.0042403" diaginertia="6.9397e-07 6.62865e-07 2.10915e-07"/>
        <joint name="l_ring_proximal_joint" pos="0 0 0" axis="0 0 -1" range="0 1.47" actuatorfrcrange="-1 1"/>
        <geom type="mesh" contype="0" conaffinity="0" group="1" density="0" mesh="left_index_proximal"/>
        <geom type="mesh" mesh="left_index_proximal"/>

        <body name="l_ring_intermediate" pos="-0.0024229 -0.032041 -0.001">
          <inertial pos="0.0021753 -0.019567 -0.005" quat="0.528695 0.469554 -0.528695 0.469554"
                    mass="0.0045683" diaginertia="7.8177e-07 7.72448e-07 8.4722e-08"/>
          <joint name="l_ring_intermediate_joint" pos="0 0 0" axis="0 0 -1" range="-0.04545 1.56" actuatorfrcrange="-1 1"/>
          <geom type="mesh" contype="0" conaffinity="0" group="1" density="0" mesh="left_index_intermediate"/>
          <geom type="mesh" mesh="left_index_intermediate"/>
        </body>
      </body>

      <!-- Pinky finger -->
      <body name="l_pinky_proximal" pos="0.00028533 -0.13571 -0.025488" quat="0.99863 0.0523361 0 0">
        <inertial pos="0.001297 -0.011934 -0.0060001" quat="0.489693 0.51013 -0.489653 0.510106"
                  mass="0.0042403" diaginertia="6.9397e-07 6.62865e-07 2.10915e-07"/>
        <joint name="l_pinky_proximal_joint" pos="0 0 0" axis="0 0 -1" range="0 1.47" actuatorfrcrange="-1 1"/>
        <geom type="mesh" contype="0" conaffinity="0" group="1" density="0" mesh="left_index_proximal"/>
        <geom type="mesh" mesh="left_index_proximal"/>

        <body name="l_pinky_intermediate" pos="-0.0024229 -0.032041 -0.001">
          <inertial pos="0.0024748 -0.016203 -0.0050031" quat="0.528862 0.47398 -0.524799 0.469291"
                    mass="0.0035996" diaginertia="4.4867e-07 4.43723e-07 6.56538e-08"/>
          <joint name="l_pinky_intermediate_joint" pos="0 0 0" axis="0 0 -1" range="-0.04545 1.56" actuatorfrcrange="-1 1"/>
          <geom type="mesh" contype="0" conaffinity="0" group="1" density="0" mesh="left_pinky_intermediate"/>
          <geom type="mesh" mesh="left_pinky_intermediate"/>
        </body>
      </body>

    </body>  <!-- inspire_palm_l -->
  </worldbody>

  <actuator>
    <position name="l_th_yaw_act"   joint="l_thumb_proximal_yaw_joint"   kp="3.0" kv="0.01" ctrlrange="0 1.308"/>
    <position name="l_th_pitch_act" joint="l_thumb_proximal_pitch_joint"  kp="3.0" kv="0.01" ctrlrange="0 0.6"/>
    <position name="l_th_int_act"   joint="l_thumb_intermediate_joint"    kp="3.0" kv="0.01" ctrlrange="0 0.8"/>
    <position name="l_th_dis_act"   joint="l_thumb_distal_joint"          kp="3.0" kv="0.01" ctrlrange="0 0.4"/>

    <position name="l_if_prx_act"   joint="l_index_proximal_joint"        kp="3.0" kv="0.01" ctrlrange="0 1.47"/>
    <position name="l_if_int_act"   joint="l_index_intermediate_joint"    kp="3.0" kv="0.01" ctrlrange="-0.04545 1.56"/>

    <position name="l_mf_prx_act"   joint="l_middle_proximal_joint"       kp="3.0" kv="0.01" ctrlrange="0 1.47"/>
    <position name="l_mf_int_act"   joint="l_middle_intermediate_joint"   kp="3.0" kv="0.01" ctrlrange="-0.04545 1.56"/>

    <position name="l_rf_prx_act"   joint="l_ring_proximal_joint"         kp="3.0" kv="0.01" ctrlrange="0 1.47"/>
    <position name="l_rf_int_act"   joint="l_ring_intermediate_joint"     kp="3.0" kv="0.01" ctrlrange="-0.04545 1.56"/>

    <position name="l_pk_prx_act"   joint="l_pinky_proximal_joint"        kp="3.0" kv="0.01" ctrlrange="0 1.47"/>
    <position name="l_pk_int_act"   joint="l_pinky_intermediate_joint"    kp="3.0" kv="0.01" ctrlrange="-0.04545 1.56"/>
  </actuator>

</mujoco>
